<?xml version="1.0" ?>
<!-- =================================================================================== -->
<!-- |    This document was autogenerated by xacro from /home/markus/projects/ros2/pioneer/tuw/install/tuw_gazebo_models/share/tuw_gazebo_models/models/pioneer3dx/main.xacro | -->
<!-- |    EDITING THIS FILE BY HAND IS NOT RECOMMENDED                                 | -->
<!-- =================================================================================== -->
<robot name="pioneer3dx">
	<material name="black">
		<color rgba="0.0 0.0 0.0 1.0"/>
	</material>
	<material name="blue">
		<color rgba="0.0 0.0 0.8 1.0"/>
	</material>
	<material name="light_blue">
		<color rgba="0.39215686274509803 0.5254901960784314 0.8352941176470589 1.0"/>
	</material>
	<material name="green">
		<color rgba="0.0 0.8 0.0 1.0"/>
	</material>
	<material name="light_grey">
		<color rgba="0.5 0.5 0.5 1.0"/>
	</material>
	<material name="grey">
		<color rgba="0.2 0.2 0.2 1.0"/>
	</material>
	<material name="orange">
		<color rgba="1.0 0.4235294117647059 0.0392156862745098 1.0"/>
	</material>
	<material name="brown">
		<color rgba="0.8705882352941177 0.8117647058823529 0.7647058823529411 1.0"/>
	</material>
	<material name="red">
		<color rgba="0.8 0.0 0.0 1.0"/>
	</material>
	<material name="white">
		<color rgba="1.0 1.0 1.0 1.0"/>
	</material>
	<!-- Thanks to Martin Guenther 
  see https://github.com/uos/uos_tools/blob/fuerte/uos_common_urdf/common.xacro and
  see http://answers.gazebosim.org/question/4372/the-inertia-matrix-explained/ -->
	<!-- see https://secure.wikimedia.org/wikipedia/en/wiki/List_of_moment_of_inertia_tensors -->
	<!-- base_link -->
	<link name="base_link"/>
	<!-- Chassis -->
	<joint name="base_link_body_joint" type="fixed">
		<origin rpy="0 0 0" xyz="0 0 0.068"/>
		<parent link="base_link"/>
		<child link="body"/>
	</joint>
	<link name="body">
		<visual>
			<origin rpy="0 0 0" xyz="-0.045 0 0.085"/>
			<geometry>
				<mesh filename="file:///home/markus/projects/ros2/pioneer/tuw/install/tuw_gazebo_models/share/tuw_gazebo_models/models/pioneer3dx/body/meshes/chassis.dae"/>
			</geometry>
			<material name="ChassisRed">
				<color rgba="0.851 0.0 0.0 1.0"/>
			</material>
		</visual>
		<collision>
			<origin rpy="0 0 0" xyz="0.01 0 0.09"/>
			<geometry>
				<cylinder length="0.17" radius="0.17"/>
			</geometry>
			<!--origin xyz="-0.045 0 0.148" rpy="0 0 0"/>
      <geometry>  
        <mesh filename="file://${model_dir}/meshes/body/chassis.dae"/>
      </geometry-->
		</collision>
		<inertial>
			<mass value="9.0"/>
			<origin rpy="0 0 0" xyz="-0.04 0 0.15"/>
			<inertia ixx="0.06854997258000001" ixy="0.0" ixz="0.0" iyy="0.11354995457999999" iyz="0.0" izz="0.1387499445"/>
		</inertial>
	</link>
	<gazebo reference="body">
		<material value="Gazebo/Red"/>
	</gazebo>
	<!-- Top -->
	<joint name="body_top_joint" type="fixed">
		<origin rpy="0 0 0" xyz="0 0 0.245"/>
		<parent link="base_link"/>
		<child link="top"/>
	</joint>
	<link name="top">
		<visual>
			<origin rpy="0 0 0" xyz="-0.045 0 0"/>
			<geometry>
				<mesh filename="file:///home/markus/projects/ros2/pioneer/tuw/install/tuw_gazebo_models/share/tuw_gazebo_models/models/pioneer3dx/body/meshes/top.dae"/>
			</geometry>
			<material name="TopBlack">
				<color rgba="0.038 0.038 0.038 1.0"/>
			</material>
		</visual>
		<collision>
			<origin rpy="0 0 0" xyz="-0.095 0 -0.08499999999999999"/>
			<geometry>
				<cylinder length="0.17" radius="0.17"/>
			</geometry>
			<!--origin xyz="0.0 0 0.0" rpy="0 0 0"/>
      <geometry>
        <mesh filename="file://${models_dir}/pioneer3dx/body/meshes/top.dae"/>
      </geometry-->
		</collision>
		<inertial>
			<mass value="1.0"/>
			<origin rpy="0 0 0" xyz="0.00 0 0.00"/>
			<inertia ixx="0.010208412583299999" ixy="0.0" ixz="0.0" iyy="0.0168750765833" iyz="0.0" izz="0.0270833225"/>
		</inertial>
	</link>
	<gazebo reference="top">
		<material value="Gazebo/Black"/>
	</gazebo>
	<!--  mount camera tof  -->
	<joint name="top_camera_tof_joint" type="fixed">
		<origin rpy="0 0 0" xyz="0 0 0.38"/>
		<parent link="top"/>
		<child link="mount_camera_tof"/>
	</joint>
	<link name="mount_camera_tof">
		<visual>
			<origin rpy="0 0 0" xyz="-0.01 0 0.03"/>
			<geometry>
				<box size="0.01 0.12 0.12"/>
			</geometry>
			<material name="mount_camera_tof">
				<color rgba="0.8 0.8 0.8 1"/>
			</material>
		</visual>
		<visual>
			<origin rpy="0 1.5707963267948966 0" xyz="0.0 0 0.0"/>
			<geometry>
				<cylinder length="0.01" radius="0.01"/>
			</geometry>
			<material name="mount_camera_tof">
				<color rgba="0.8 0.8 0.8 1"/>
			</material>
		</visual>
	</link>
	<gazebo reference="mount_camera_tof">
		<material value="Gazebo/Grey"/>
	</gazebo>
	<!--  mount bottom left -->
	<joint name="top_mount_bottom_joint" type="fixed">
		<origin rpy="0 0 0" xyz="0 0 0"/>
		<parent link="top"/>
		<child link="mount_bottom"/>
	</joint>
	<link name="mount_bottom">
		<!-- right base bar -->
		<visual>
			<origin xyz="-0.04 +0.135 0.01"/>
			<geometry>
				<box size="0.31 0.04 0.02"/>
			</geometry>
			<material name="aluminium_bar">
				<color rgba="0.8 0.8 0.8 1"/>
			</material>
		</visual>
		<collision>
			<origin xyz="-0.04 +0.135 0.01"/>
			<geometry>
				<box size="0.31 0.04 0.02"/>
			</geometry>
		</collision>
		<!-- left base bar -->
		<visual>
			<origin xyz="-0.04 -0.135 0.01"/>
			<geometry>
				<box size="0.31 0.04 0.02"/>
			</geometry>
			<material name="aluminium_bar">
				<color rgba="0.8 0.8 0.8 1"/>
			</material>
		</visual>
		<collision>
			<origin xyz="-0.04 -0.135 0.01"/>
			<geometry>
				<box size="0.31 0.04 0.02"/>
			</geometry>
		</collision>
		<!-- right column -->
		<visual>
			<origin xyz="-0.0 +0.125 0.48000000000000004"/>
			<geometry>
				<box size="0.02 0.02 0.92"/>
			</geometry>
			<material name="aluminium_bar">
				<color rgba="0.8 0.8 0.8 1"/>
			</material>
		</visual>
		<collision>
			<origin xyz="-0.0 +0.125 0.48000000000000004"/>
			<geometry>
				<box size="0.02 0.02 0.92"/>
			</geometry>
		</collision>
		<!-- left column -->
		<visual>
			<origin xyz="-0.0 -0.125 0.48000000000000004"/>
			<geometry>
				<box size="0.02 0.02 0.92"/>
			</geometry>
			<material name="aluminium_bar">
				<color rgba="0.8 0.8 0.8 1"/>
			</material>
		</visual>
		<collision>
			<origin xyz="-0.0 -0.125 0.48000000000000004"/>
			<geometry>
				<box size="0.02 0.02 0.92"/>
			</geometry>
		</collision>
		<!-- laser bar -->
		<visual>
			<origin xyz="0.02 0 0.19"/>
			<geometry>
				<box size="0.02 0.27 0.02 "/>
			</geometry>
			<material name="aluminium_bar">
				<color rgba="0.8 0.8 0.8 1"/>
			</material>
		</visual>
		<collision>
			<origin xyz="0.02 0 0.19"/>
			<geometry>
				<box size="0.02 0.27 0.02 "/>
			</geometry>
		</collision>
		<!-- camera tof bar low -->
		<visual>
			<origin xyz="-0.02 0 0.36"/>
			<geometry>
				<box size="0.02 0.27 0.02 "/>
			</geometry>
			<material name="aluminium_bar">
				<color rgba="0.8 0.8 0.8 1"/>
			</material>
		</visual>
		<collision>
			<origin xyz="-0.02 0 0.36"/>
			<geometry>
				<box size="0.02 0.27 0.02 "/>
			</geometry>
		</collision>
		<!-- camera tof bar bottom -->
		<visual>
			<origin xyz="-0.02 0 0.47"/>
			<geometry>
				<box size="0.02 0.27 0.02 "/>
			</geometry>
			<material name="aluminium_bar">
				<color rgba="0.8 0.8 0.8 1"/>
			</material>
		</visual>
		<collision>
			<origin xyz="-0.02 0 0.47"/>
			<geometry>
				<box size="0.02 0.27 0.02 "/>
			</geometry>
		</collision>
		<!-- Top bar -->
		<visual>
			<origin xyz="0 0 0.9500000000000001"/>
			<geometry>
				<box size="0.02 0.30 0.02 "/>
			</geometry>
			<material name="aluminium_bar">
				<color rgba="0.8 0.8 0.8 1"/>
			</material>
		</visual>
		<collision>
			<origin xyz="0 0 0.9500000000000001"/>
			<geometry>
				<box size="0.02 0.30 0.02 "/>
			</geometry>
		</collision>
	</link>
	<gazebo reference="mount_bottom">
		<material value="Gazebo/Grey"/>
	</gazebo>
	<!-- Front Sonar -->
	<joint name="body_sonar_joint" type="fixed">
		<origin rpy="0 0 0" xyz="0.109 0 0.15"/>
		<parent link="body"/>
		<child link="sonar"/>
	</joint>
	<link name="sonar">
		<inertial>
			<mass value="0.01"/>
			<origin xyz="0 0 0"/>
			<inertia ixx="1.666666e-07" ixy="0.0" ixz="0.0" iyy="1.666666e-07" iyz="0.0" izz="1.666666e-07"/>
		</inertial>
		<visual>
			<origin rpy="0 0 0" xyz="0 0 0"/>
			<geometry>
				<mesh filename="file:///home/markus/projects/ros2/pioneer/tuw/install/tuw_gazebo_models/share/tuw_gazebo_models/models/pioneer3dx/body/meshes/back_sonar.dae"/>
			</geometry>
			<material name="SonarYellow">
				<color rgba="0.715 0.583 0.210 1.0"/>
			</material>
		</visual>
		<collision>
			<origin rpy="0 0 0" xyz="0 0 0"/>
			<geometry>
				<box size="0.001 0.001 0.001"/>
			</geometry>
		</collision>
	</link>
	<gazebo reference="sonar">
		<material value="Gazebo/Yellow"/>
	</gazebo>
	<joint name="body_battery0_joint" type="fixed">
		<origin rpy="0 0 0" xyz="-0.14 0.0 0.062"/>
		<parent link="body"/>
		<child link="battery0"/>
	</joint>
	<link name="battery0">
		<visual name="battery0_visual">
			<origin rpy="0 0 0" xyz="0 0 0"/>
			<geometry name="battery0_geometry">
				<box size="0.151 0.065 0.094"/>
			</geometry>
			<material name="battery0_material">
				<color rgba="0.038 0.038 0.038 1.0"/>
			</material>
		</visual>
		<inertial>
			<mass value="2.5"/>
			<origin xyz="0 0 0"/>
			<inertia ixx="0.00272104057825" ixy="0.0" ixz="0.0" iyy="0.0065910390302499995" iyz="0.0" izz="0.0056304144145"/>
		</inertial>
	</link>
	<gazebo reference="battery0">
		<material value="Gazebo/Black"/>
	</gazebo>
	<!-- Swivel -->
	<joint name="swivel_joint" type="continuous">
		<origin rpy="0 0 0" xyz="-0.185 0    0.0535"/>
		<axis xyz="0 0 1"/>
		<anchor xyz="0 0 0"/>
		<!--limit effort="100" velocity="100" k_velocity="0"/-->
		<joint_properties damping="0.1" friction="0.0"/>
		<parent link="base_link"/>
		<child link="swivel"/>
	</joint>
	<link name="swivel">
		<inertial>
			<mass value="0.1"/>
			<origin xyz="0 0 0"/>
			<inertia ixx="0.01" ixy="0" ixz="0" iyy="0.01" iyz="0" izz="0.01"/>
		</inertial>
		<visual>
			<origin rpy="0 0 0" xyz="0 0 0"/>
			<geometry>
				<mesh filename="file:///home/markus/projects/ros2/pioneer/tuw/install/tuw_gazebo_models/share/tuw_gazebo_models/models/pioneer3dx/body/meshes/swivel.stl"/>
			</geometry>
			<material name="swivel">
				<color rgba="0.5 0.5 0.5 1"/>
			</material>
		</visual>
		<collision>
			<origin rpy="0 0 0" xyz="0 0 0"/>
			<geometry>
				<box size="0.001 0.001 0.001"/>
			</geometry>
		</collision>
	</link>
	<gazebo reference="swivel">
		<material value="Gazebo/Grey"/>
	</gazebo>
	<!-- Center Wheel -->
	<joint name="swivel_wheel_joint" type="continuous">
		<origin rpy="0 0 0" xyz="-0.026 0 -0.016"/>
		<axis xyz="0 1 0"/>
		<anchor xyz="0 0 0"/>
		<!--limit effort="100" velocity="100" k_velocity="0"/-->
		<joint_properties damping="0.0" friction="0.0"/>
		<parent link="swivel"/>
		<child link="swivel_wheel"/>
	</joint>
	<link name="swivel_wheel">
		<inertial>
			<mass value="0.1"/>
			<origin xyz="0 0 0"/>
			<inertia ixx="0.012411765597" ixy="-0.000711733678" ixz="0.00050272983" iyy="0.015218160428" iyz="-0.000004273467" izz="0.011763977943"/>
		</inertial>
		<visual>
			<origin rpy="0 0 0" xyz="0 0 0"/>
			<geometry>
				<mesh filename="file:///home/markus/projects/ros2/pioneer/tuw/install/tuw_gazebo_models/share/tuw_gazebo_models/models/pioneer3dx/body/meshes/center_wheel.stl"/>
			</geometry>
			<material name="WheelBlack">
				<color rgba="0.117 0.117 0.117 1"/>
			</material>
		</visual>
		<collision>
			<origin rpy="-1.57079635 0 0" xyz="0 0 0"/>
			<geometry>
				<!--<mesh filename="meshes/center_wheel.stl"/>-->
				<cylinder length="0.001" radius="0.0375"/>
				<!--radius="0.0375"-->
			</geometry>
		</collision>
	</link>
	<gazebo reference="swivel_wheel">
		<material value="Gazebo/Black"/>
		<mu1 value="0.7"/>
		<mu2 value="0.7"/>
		<minDepth value="0.002"/>
		<!--kp value="1000000.0"/-->
		<!--kd value="10.0"/-->
	</gazebo>
	<!-- Center Hubcap -->
	<joint name="swivel_hubcap_joint" type="fixed">
		<origin rpy="0 0 0" xyz="0 0 0"/>
		<parent link="swivel_wheel"/>
		<child link="swivel_hubcap"/>
	</joint>
	<link name="swivel_hubcap">
		<inertial>
			<mass value="0.01"/>
			<origin xyz="0 0 0"/>
			<inertia ixx="0.012411765597" ixy="-0.000711733678" ixz="0.00050272983" iyy="0.015218160428" iyz="-0.000004273467" izz="0.011763977943"/>
		</inertial>
		<visual>
			<origin rpy="0 0 0" xyz="0 0 0"/>
			<geometry>
				<mesh filename="file:///home/markus/projects/ros2/pioneer/tuw/install/tuw_gazebo_models/share/tuw_gazebo_models/models/pioneer3dx/body/meshes/center_hubcap.stl"/>
			</geometry>
			<material name="swivel">
				<color rgba="0.5 0.5 0.5 1"/>
			</material>
		</visual>
		<collision>
			<origin rpy="0 0 0" xyz="0 0 0"/>
			<geometry>
				<box size="0.001 0.001 0.001"/>
			</geometry>
		</collision>
	</link>
	<gazebo reference="swivel_hubcap">
		<material value="Gazebo/Grey"/>
		<mu1 value="0.7"/>
		<mu2 value="0.7"/>
		<minDepth value="0.002"/>
		<!--kp value="1000000.0"/-->
		<!--kd value="10.0"/-->
	</gazebo>
	<!-- Wheel -->
	<joint name="right_wheel_joint" type="continuous">
		<origin rpy="0 0 0" xyz=" 0    -0.165 0.097"/>
		<axis xyz="0 1 0"/>
		<parent link="base_link"/>
		<child link="right_wheel"/>
	</joint>
	<link name="right_wheel">
		<inertial>
			<mass value="0.5"/>
			<origin xyz="0 0 0"/>
			<inertia ixx="0.012411765597" ixy="0" ixz="0" iyy="0.015218160428" iyz="0" izz="0.011763977943"/>
		</inertial>
		<visual>
			<origin rpy="0 0 0" xyz="0 0 0"/>
			<geometry>
				<mesh filename="file:///home/markus/projects/ros2/pioneer/tuw/install/tuw_gazebo_models/share/tuw_gazebo_models/models/pioneer3dx/body/meshes/wheel.dae"/>
			</geometry>
			<material name="WheelBlack">
				<color rgba="0.117 0.117 0.117 1"/>
			</material>
		</visual>
		<collision>
			<origin rpy="1.5707963267948966 0 0" xyz="0 0 0"/>
			<geometry>
				<cylinder length="0.001" radius="0.097"/>
				<!--<mesh filename="${meshes}/${name}_wheel.stl"/>-->
			</geometry>
		</collision>
	</link>
	<gazebo reference="right_wheel">
		<material value="Gazebo/Black"/>
		<mu1 value="0.7"/>
		<mu2 value="0.7"/>
		<minDepth value="0.002"/>
		<!--kp value="1000000.0"/-->
		<!--kd value="10.0"/-->
	</gazebo>
	<!-- Hubcap -->
	<joint name="right_hub_joint" type="fixed">
		<origin rpy="0 0 0" xyz="0 0 0"/>
		<axis xyz="0 1 0"/>
		<parent link="right_wheel"/>
		<child link="right_hub"/>
	</joint>
	<link name="right_hub">
		<inertial>
			<mass value="0.01"/>
			<origin xyz="0 0 0"/>
			<inertia ixx="0.012411765597" ixy="0" ixz="0" iyy="0.015218160428" iyz="0" izz="0.011763977943"/>
		</inertial>
		<visual>
			<origin rpy="0 0 0" xyz="0 0 0"/>
			<geometry>
				<mesh filename="file:///home/markus/projects/ros2/pioneer/tuw/install/tuw_gazebo_models/share/tuw_gazebo_models/models/pioneer3dx/body/meshes/hubcap.dae"/>
			</geometry>
			<material name="HubcapYellow">
				<color rgba="1.0 0.811 0.151 1.0"/>
			</material>
		</visual>
		<collision>
			<origin rpy="0 0 0" xyz="0 0 0"/>
			<geometry>
				<box size="0.001 0.001 0.001"/>
			</geometry>
		</collision>
	</link>
	<gazebo reference="right_hub">
		<material value="Gazebo/Yellow"/>
	</gazebo>
	<!-- Wheel -->
	<joint name="left_wheel_joint" type="continuous">
		<origin rpy="0 0 0" xyz=" 0     0.165 0.097"/>
		<axis xyz="0 1 0"/>
		<parent link="base_link"/>
		<child link="left_wheel"/>
	</joint>
	<link name="left_wheel">
		<inertial>
			<mass value="0.5"/>
			<origin xyz="0 0 0"/>
			<inertia ixx="0.012411765597" ixy="0" ixz="0" iyy="0.015218160428" iyz="0" izz="0.011763977943"/>
		</inertial>
		<visual>
			<origin rpy="0 0 0" xyz="0 0 0"/>
			<geometry>
				<mesh filename="file:///home/markus/projects/ros2/pioneer/tuw/install/tuw_gazebo_models/share/tuw_gazebo_models/models/pioneer3dx/body/meshes/wheel.dae"/>
			</geometry>
			<material name="WheelBlack">
				<color rgba="0.117 0.117 0.117 1"/>
			</material>
		</visual>
		<collision>
			<origin rpy="1.5707963267948966 0 0" xyz="0 0 0"/>
			<geometry>
				<cylinder length="0.001" radius="0.097"/>
				<!--<mesh filename="${meshes}/${name}_wheel.stl"/>-->
			</geometry>
		</collision>
	</link>
	<gazebo reference="left_wheel">
		<material value="Gazebo/Black"/>
		<mu1 value="0.7"/>
		<mu2 value="0.7"/>
		<minDepth value="0.002"/>
		<!--kp value="1000000.0"/-->
		<!--kd value="10.0"/-->
	</gazebo>
	<!-- Hubcap -->
	<joint name="left_hub_joint" type="fixed">
		<origin rpy="0 0 0" xyz="0 0 0"/>
		<axis xyz="0 1 0"/>
		<parent link="left_wheel"/>
		<child link="left_hub"/>
	</joint>
	<link name="left_hub">
		<inertial>
			<mass value="0.01"/>
			<origin xyz="0 0 0"/>
			<inertia ixx="0.012411765597" ixy="0" ixz="0" iyy="0.015218160428" iyz="0" izz="0.011763977943"/>
		</inertial>
		<visual>
			<origin rpy="0 0 0" xyz="0 0 0"/>
			<geometry>
				<mesh filename="file:///home/markus/projects/ros2/pioneer/tuw/install/tuw_gazebo_models/share/tuw_gazebo_models/models/pioneer3dx/body/meshes/hubcap.dae"/>
			</geometry>
			<material name="HubcapYellow">
				<color rgba="1.0 0.811 0.151 1.0"/>
			</material>
		</visual>
		<collision>
			<origin rpy="0 0 0" xyz="0 0 0"/>
			<geometry>
				<box size="0.001 0.001 0.001"/>
			</geometry>
		</collision>
	</link>
	<gazebo reference="left_hub">
		<material value="Gazebo/Yellow"/>
	</gazebo>
	<gazebo>
		<plugin filename="libtuw_gazebo_ros_diff_drive.so" name="diff_drive">
			<ros>
				<namespace/>
				<remapping>cmd_vel:=cmd_vel</remapping>
				<remapping>odom:=odom</remapping>
			</ros>
			<left_joint>left_wheel_joint</left_joint>
			<right_joint>right_wheel_joint</right_joint>
			<wheel_separation>0.3</wheel_separation>
			<wheel_diameter>0.18</wheel_diameter>
			<max_wheel_torque>10</max_wheel_torque>
			<max_wheel_acceleration>1.5</max_wheel_acceleration>
			<publish_odom>true</publish_odom>
			<publish_odom_tf>true</publish_odom_tf>
			<publish_wheel_tf>false</publish_wheel_tf>
			<odometry_frame>odom</odometry_frame>
			<robot_base_frame>base_link</robot_base_frame>
		</plugin>
	</gazebo>
	<gazebo>
		<plugin filename="libgazebo_ros_joint_state_publisher.so" name="gazebo_ros_joint_state_publisher">
			<ros>
				<namespace/>
				<remapping>joint_states:=joint_states</remapping>
			</ros>
			<update_rate>10</update_rate>
			<joint_name>left_wheel_joint</joint_name>
			<joint_name>right_wheel_joint</joint_name>
			<joint_name>swivel_joint</joint_name>
			<joint_name>swivel_wheel_joint</joint_name>
		</plugin>
	</gazebo>
	<joint name="top_laser0_joint" type="fixed">
		<axis xyz="0 0 1"/>
		<origin rpy="0 0 0" xyz="0.15 0.0 0.06"/>
		<parent link="top"/>
		<child link="laser0"/>
	</joint>
	<link name="laser0">
		<collision>
			<origin rpy="0 0 0" xyz="0 0 -0.025"/>
			<geometry>
				<box size="0.05 0.05 0.05"/>
			</geometry>
		</collision>
		<visual>
			<origin rpy="0 0 0" xyz="0 0 -0.025"/>
			<geometry>
				<mesh filename="file:///home/markus/projects/ros2/pioneer/tuw/install/tuw_gazebo_models/share/tuw_gazebo_models/models/hokuyo/meshes/hokuyo.dae"/>
			</geometry>
		</visual>
		<inertial>
			<mass value="1e-2"/>
			<origin rpy="0 0 0" xyz="0 0 -0.025"/>
			<inertia ixx="1e-6" ixy="0" ixz="0" iyy="1e-6" iyz="0" izz="1e-6"/>
		</inertial>
	</link>
	<!-- ray sensor -->
	<gazebo reference="laser0">
		<sensor name="laser0_sensor" type="gpu_ray">
			<pose>0 0 0 0 0 0</pose>
			<update_rate>30</update_rate>
			<visualize>True</visualize>
			<always_on>true</always_on>
			<ray>
				<scan>
					<horizontal>
						<samples>683</samples>
						<resolution>1.0</resolution>
						<min_angle>-2.35619449019</min_angle>
						<max_angle>2.35619449019</max_angle>
					</horizontal>
				</scan>
				<range>
					<min>0.05</min>
					<max>10</max>
				</range>
				<noise>
					<type>gaussian</type>
					<mean>0.0</mean>
					<stddev>0.01</stddev>
				</noise>
			</ray>
			<plugin filename="libgazebo_ros_ray_sensor.so" name="laser0_laserscan">
				<ros>
					<namespace/>
					<remapping>~/out:=scan_raw</remapping>
				</ros>
				<output_type>sensor_msgs/LaserScan</output_type>
				<frame_name>laser0</frame_name>
			</plugin>
		</sensor>
	</gazebo>
</robot>
